Workbook

Sheet Diccionario
A1: Diccionario de variables — Seguridad vial (MSSV)
A2: Catálogo de variables por categoría · mismo formato del libro de higiene
A4: Categoría | B4: Nombre de la variable | C4: Magnitud (símbolo) | D4: Unidad | E4: Tipo de dato | F4: Norma / criterio
A5: Generalidad / PESV | B5: Cumplimiento por paso PESV | C5: — | D5: Cumple/Parcial/No/N.A. | E5: Inspección | F5: Res. 40595/2022
A6: Generalidad / PESV | B6: % de avance por paso | C6: %av | D6: % | E6: Inspección | F6: —
A7: Generalidad / PESV | B7: % cumplimiento PESV global | C7: %PESV | D7: % | E7: Cálculo | F7: —
A8: Inventario | B8: Actores viales por tipo | C8: — | D8: conteo | E8: Medición | F8: —
A9: Inventario | B9: Parque automotor por tipo | C9: — | D9: conteo | E9: Medición | F9: —
A10: Inventario | B10: Rutas / ciudades / sedes | C10: — | D10: conteo | E10: Medición | F10: —
A11: Vehículo | B11: Vigencia SOAT / RTM / póliza | C11: — | D11: fecha · días | E11: Medición/Cálculo | F11: vigente
A12: Vehículo | B12: Comparendos | C12: — | D12: conteo | E12: Medición | F12: 0
A13: Vehículo | B13: Cumplimiento plan de mantenimiento | C13: — | D13: % | E13: Cálculo | F13: 100 %
A14: Vehículo | B14: Prueba de frenado | C14: — | D14: OK/Revisar | E14: Inspección | F14: eficaz
A15: Vehículo | B15: Alineación y balanceo | C15: — | D15: fecha | E15: Inspección | F15: al día
... A42: Análisis | B42: Efectividad de intervención (antes/después) | C42: Δ | D42: % reducción | E42: Cálculo | F42: —

Sheet Hoja 1 · Generalidad
A1: Hoja 1 · Generalidad — Cumplimiento PESV e inventario de movilidad
A2: Registro base MSSV · Resolución 40595 de 2022 (4 fases, 24 pasos)
A4: Autodiagnóstico PESV — 24 pasos (Resolución 40595 de 2022)
A5: Fase | B5: Paso | C5: Elemento del PESV | D5: Nivel aplicable | E5: Cumplimiento | F5: % avance | G5: Evidencia | H5: Observaciones
A6: F1 | B6: 1 | C6: Líder del diseño e implementación del PESV | D6: Todos | E6: Cumple | F6: 100
A7: F1 | B7: 2 | C7: Comité de seguridad vial | D7: Estándar y Avanzado | E7: Cumple | F7: 100
A8: F1 | B8: 3 | C8: Política de seguridad vial de la organización | D8: Todos | E8: Cumple | F8: 100
A9: F1 | B9: 4 | C9: Liderazgo, compromiso y corresponsabilidad del nivel directivo | D9: Todos | E9: Cumple | F9: 100
A10: F1 | B10: 5 | C10: Diagnóstico | D10: Todos | E10: Cumple | F10: 100
A11: F1 | B11: 6 | C11: Caracterización, evaluación y control de riesgos | D11: Todos | E11: Parcial | F11: 70
A12: F1 | B12: 7 | C12: Objetivos y metas del PESV | D12: Todos | E12: Cumple | F12: 100
A13: F1 | B13: 8 | C13: Programas de gestión de riesgos críticos y factores de desempeño | D13: Todos | E13: Parcial | F13: 60
A14: F2 | B14: 9 | C14: Plan anual de trabajo | D14: Todos | E14: Cumple | F14: 100
A15: F2 | B15: 10 | C15: Competencia y plan anual de formación | D15: Todos | E15: Parcial | F15: 80
A16: F2 | B16: 11 | C16: Comportamiento humano (selección, documentación y conducta segura) | D16: Todos | E16: Parcial | F16: 70
A17: F2 | B17: 12 | C17: Atención a víctimas — protocolo de atención | D17: Todos | E17: Cumple | F17: 100
... A29: F4 | B29: 24 | C29: Mecanismos de comunicación y participación | D29: Todos | E29: Cumple | F29: 100
C30: % de cumplimiento PESV (promedio de avance) | F30: =AVERAGE(F6:F29) -> 75
A32: Inventario de movilidad — actores viales
A33: Tipo | D33: Cantidad | E33: Observaciones
A34: Peatones (colaboradores que se desplazan a pie) | D34: 45
A35: Ciclistas | D35: 8
A36: Usuarios de monopatín / patineta eléctrica | D36: 6
A37: Motociclistas | D37: 20
A38: Conductores de vehículo liviano | D38: 30
A39: Conductores de vehículo pesado | D39: 15
A40: Operadores de equipo especial (grúa, montacargas) | D40: 5
A41: Pasajeros | D41: 60
A42: Total actores viales | D42: =SUM(D34:D41) -> 189
A44: Parque automotor
A45: Tipo | D45: Cantidad | E45: Observaciones
A46: Vehículos livianos | D46: 25
A47: Vehículos pesados / carga | D47: 12
A48: Motocicletas | D48: 18
A49: Bicicletas / monopatines (empresa) | D49: 10
A50: Equipo especial (grúas, montacargas) | D50: 4
A51: Total vehículos | D51: =SUM(D46:D50) -> 69
A53: Cobertura operacional
A54: Concepto | D54: Cantidad | E54: Observaciones
A55: Sedes | D55: 3
...

Sheet Hoja 2 · Vehículos
A1: Hoja 2 · Vehículos — inventario, mantenimiento y operación
A2: Filtrable por placa, ciudad, zona, sede, ruta o conductor. Admite varios conductores. Días, anomalía y alerta se calculan solos.
A4: Identificación | E4: Ubicación y asignación | J4: Documentos y vencimientos | P4: Comparendos | Q4: Rutina de mantenimiento | Z4: Combustible y rendimiento | AD4: Ingeniería del vehículo | AG4: Estado
A5: Placa | B5: Tipo | C5: Marca / línea | D5: Modelo (año) | E5: Ciudad | F5: Zona | G5: Sede | H5: Ruta(s) asignada(s) | I5: Conductor(es) asignado(s) | J5: SOAT vence | K5: Días SOAT | L5: RTM vence | M5: Días RTM | N5: Póliza RC vence | O5: Tarjeta operación vence | P5: Comparendos (RUNT) | Q5: Últ. mantenimiento | R5: Km actual | S5: Km próx. mant. | T5: Cambio de aceite | U5: Prueba de frenado | V5: Alineación y balanceo | W5: Llantas – labrado (mm) | X5: Luces y señales | Y5: Preoperacional (últ.) | Z5: Consumo (gal/mes) | AA5: Rendimiento (km/gal) | AB5: Rendimiento base (km/gal) | AC5: Anomalía consumo (%) | AD5: Seguridad activa (ABS/ESP) | AE5: Seguridad pasiva (airbag/cinturón) | AF5: GPS / telemetría | AG5: Alerta
A6: ABC123 | B6: Camioneta | C6: Toyota Hilux | D6: 2021 | E6: Bogotá | F6: Norte | G6: Planta principal | H6: R-01, R-03 | I6: Juan Pérez / Luis Gómez | J6: 46254 | K6: =J6-TODAY() -> 19 | L6: 46397 | M6: =L6-TODAY() -> 162 | N6: 46327 | O6: 46447 | P6: 1 | Q6: 46152 | R6: 82000 | S6: 85000 | T6: 46152 | U6: OK | V6: 46132 | W6: 5 | X6: OK | Y6: 46231 | Z6: 120 | AA6: 28 | AB6: 30 | AC6: =IF(AB6=0,0,ROUND((AB6-AA6)/AB6*100,0)) -> 7 | AD6: Sí | AE6: Sí | AF6: Sí | AG6: =IF(OR(K6<=0,M6<=0),"Vencido",IF(OR(K6<=30,M6<=30,P6>0,R6>=S6,AC6>=15,W6<2,U6="Falla"),"Alerta","OK")) -> Alerta
A7: DEF456 | B7: Furgón | C7: NPR 4T | D7: 2019 | E7: Medellín | F7: Sur | G7: Sede Medellín | H7: R-05 | I7: Ana Ruiz | J7: 46213 | K7: =J7-TODAY() -> -22 | L7: 46266 | M7: =L7-TODAY() -> 31 | N7: 46310 | O7: 46357 | P7: 0 | Q7: 46174 | R7: 140000 | S7: 142000 | T7: 46174 | U7: Revisar | V7: 46096 | W7: 3 | X7: OK | Y7: 46223 | Z7: 210 | AA7: 12 | AB7: 14 | AC7: =IF(AB7=0,0,ROUND((AB7-AA7)/AB7*100,0)) -> 14 | AD7: No | AE7: Sí | AF7: Sí | AG7: =IF(OR(K7<=0,M7<=0),"Vencido",IF(OR(K7<=30,M7<=30,P7>0,R7>=S7,AC7>=15,W7<2,U7="Falla"),"Alerta","OK")) -> Vencido
A8: GHI789 | B8: Automóvil | C8: Renault Logan | D8: 2022 | E8: Bogotá | F8: Centro | G8: Planta principal | H8: R-02 | I8: Luis Gómez / Sara León | J8: 46357 | K8: =J8-TODAY() -> 122 | L8: 46341 | M8: =L8-TODAY() -> 106 | N8: 46419 | O8: 46508 | P8: 0 | Q8: 46193 | R8: 45000 | S8: 50000 | T8: 46193 | U8: OK | V8: 46174 | W8: 6 | X8: OK | Y8: 46233 | Z8: 90 | AA8: 32 | AB8: 33 | AC8: =IF(AB8=0,0,ROUND((AB8-AA8)/AB8*100,0)) -> 3 | AD8: Sí | AE8: Sí | AF8: Sí | AG8: =IF(OR(K8<=0,M8<=0),"Vencido",IF(OR(K8<=30,M8<=30,P8>0,R8>=S8,AC8>=15,W8<2,U8="Falla"),"Alerta","OK")) -> OK
A9: JKL012 | B9: Tractocamión | C9: Kenworth T800 | D9: 2018 | E9: Cali | F9: Occidente | G9: Sede Cali | H9: R-08 | I9: Pedro Díaz | J9: 46259 | K9: =J9-TODAY() -> 24 | L9: 46239 | M9: =L9-TODAY() -> 4 | N9: 46285 | O9: 46296 | P9: 2 | Q9: 46127 | R9: 260000 | S9: 262000 | T9: 46127 | U9: OK | V9: 46063 | W9: 1 | X9: Falla | Y9: 46218 | Z9: 380 | AA9: 8 | AB9: 10 | AC9: =IF(AB9=0,0,ROUND((AB9-AA9)/AB9*100,0)) -> 20 | AD9: Sí | AE9: Sí | AF9: Sí | AG9: =IF(OR(K9<=0,M9<=0),"Vencido",IF(OR(K9<=30,M9<=30,P9>0,R9>=S9,AC9>=15,W9<2,U9="Falla"),"Alerta","OK")) -> Alerta
A10: MNO345 | B10: Grúa | C10: Grúa telescópica | D10: 2020 | E10: Bogotá | F10: Industrial | G10: Planta principal | H10: N/A | I10: Sara León | J10: 46419 | K10: =J10-TODAY() -> 184 | L10: 46305 | M10: =L10-TODAY() -> 70 | N10: 46392 | O10: 46419 | P10: 0 | Q10: 46204 | R10: 30000 | S10: 35000 | T10: 46204 | U10: OK | V10: 46143 | W10: 7 | X10: OK | Y10: 46228 | Z10: 150 | AA10: 6 | AB10: 6 | AC10: =IF(AB10=0,0,ROUND((AB10-AA10)/AB10*100,0)) -> 0 | AD10: Sí | AE10: Sí | AF10: Sí | AG10: =IF(OR(K10<=0,M10<=0),"Vencido",IF(OR(K10<=30,M10<=30,P10>0,R10>=S10,AC10>=15,W10<2,U10="Falla"),"Alerta","OK")) -> OK

Sheet Hoja 3 · Personas
A1: Hoja 3 · Personas — competencias y formación del actor vial
A2: Cursos, evaluaciones cognitivas (incluye manejo comentado nocturno) y licencia por conductor. ICC, resultado y alerta se calculan solos.
A4: Identificación | H4: Licencia y aptitud | M4: Formación | Q4: Evaluaciones cognitivas | Z4: Índice y resultado | AB4: Estado
A5: Documento | B5: Nombre | C5: Cargo | D5: Actor vial | E5: Ciudad | F5: Sede | G5: Vehículo(s) asignado(s) | H5: Lic. categoría | I5: Licencia vence | J5: Días licencia | K5: Psicosensométrico vence | L5: Estado de salud | M5: N° cursos SV | N5: Horas de formación | O5: Última capacitación | P5: Reentrenamiento programado | Q5: Conducción segura | R5: Manejo defensivo | S5: Manejo comentado diurno | T5: Manejo comentado nocturno | U5: Conocimiento del vehículo | V5: Normas de tránsito | W5: Gestión de fatiga | X5: Investigación de siniestros | Y5: Primeros auxilios | Z5: ICC | AA5: Resultado | AB5: Alerta
A6: 79123456 | B6: Juan Pérez | C6: Conductor | D6: Conductor liviano | E6: Bogotá | F6: Planta principal | G6: ABC123 | H6: C1 | I6: 46447 | J6: =I6-TODAY() -> 212 | K6: 46447 | L6: Apto | M6: 3 | N6: 24 | O6: 46122 | P6: 46305 | Q6: 88 | R6: 90 | S6: 85 | T6: 82 | U6: 90 | V6: 85 | W6: 84 | X6: 80 | Y6: 86 | Z6: =ROUND(AVERAGE(Q6:Y6),0) -> 86 | AA6: =IF(Z6>=70,"Aprobado","No aprobado") -> Aprobado | AB6: =IF(J6<=0,"Licencia vencida",IF(OR(J6<=30,Z6<70,L6="No apto"),"Alerta","OK")) -> OK
A7: 43111222 | B7: Ana Ruiz | C7: Conductora | D7: Conductor pesado | E7: Medellín | F7: Sede Medellín | G7: DEF456 | H7: C2 | I7: 46249 | J7: =I7-TODAY() -> 14 | K7: 46266 | L7: Apto | M7: 2 | N7: 16 | O7: 46086 | P7: 46270 | Q7: 70 | R7: 65 | S7: 60 | T7: 55 | U7: 70 | V7: 75 | W7: 68 | X7: 66 | Y7: 60 | Z7: =ROUND(AVERAGE(Q7:Y7),0) -> 65 | AA7: =IF(Z7>=70,"Aprobado","No aprobado") -> No aprobado | AB7: =IF(J7<=0,"Licencia vencida",IF(OR(J7<=30,Z7<70,L7="No apto"),"Alerta","OK")) -> Alerta
A8: 80222333 | B8: Luis Gómez | C8: Conductor | D8: Conductor liviano | E8: Bogotá | F8: Planta principal | G8: ABC123 / GHI789 | H8: B1 | I8: 46204 | J8: =I8-TODAY() -> -31 | K8: 46357 | L8: Apto | M8: 4 | N8: 32 | O8: 46143 | P8: 46327 | Q8: 82 | R8: 80 | S8: 78 | T8: 75 | U8: 85 | V8: 88 | W8: 80 | X8: 79 | Y8: 80 | Z8: =ROUND(AVERAGE(Q8:Y8),0) -> 81 | AA8: =IF(Z8>=70,"Aprobado","No aprobado") -> Aprobado | AB8: =IF(J8<=0,"Licencia vencida",IF(OR(J8<=30,Z8<70,L8="No apto"),"Alerta","OK")) -> Licencia vencida
A9: 16333444 | B9: Pedro Díaz | C9: Conductor | D9: Conductor pesado | E9: Cali | F9: Sede Cali | G9: JKL012 | H9: C3 | I9: 46539 | J9: =I9-TODAY() -> 304 | K9: 46296 | L9: No apto | M9: 1 | N9: 8 | O9: 46068 | P9: 46249 | Q9: 55 | R9: 50 | S9: 45 | T9: 42 | U9: 60 | V9: 58 | W9: 52 | X9: 50 | Y9: 48 | Z9: =ROUND(AVERAGE(Q9:Y9),0) -> 51 | AA9: =IF(Z9>=70,"Aprobado","No aprobado") -> No aprobado | AB9: =IF(J9<=0,"Licencia vencida",IF(OR(J9<=30,Z9<70,L9="No apto"),"Alerta","OK")) -> Alerta
A10: 52444555 | B10: Sara León | C10: Operadora | D10: Operador equipo especial | E10: Bogotá | F10: Planta principal | G10: MNO345 / GHI789 | H10: C1 | I10: 46357 | J10: =I10-TODAY() -> 122 | K10: 46397 | L10: Apto | M10: 5 | N10: 40 | O10: 46174 | P10: 46357 | Q10: 92 | R10: 95 | S10: 90 | T10: 88 | U10: 88 | V10: 94 | W10: 90 | X10: 86 | Y10: 90 | Z10: =ROUND(AVERAGE(Q10:Y10),0) -> 90 | AA10: =IF(Z10>=70,"Aprobado","No aprobado") -> Aprobado | AB10: =IF(J10<=0,"Licencia vencida",IF(OR(J10<=30,Z10<70,L10="No apto"),"Alerta","OK")) -> OK

Sheet Hoja 4 · Rutograma
A1: Hoja 4 · Rutograma — análisis de riesgo de ruta
A2: Formato tipo TTI: información general, organismos de apoyo, mapa, análisis de ruta y puntos.
A4: Encabezado
A5: Código | B5: XXXX | D5: Versión | E5: 01
A6: Fecha | B6: 31/05/2025 | D6: ID Ruta | E6: R-01
A7: Cliente / Proyecto | B7: EMPRESA CLIENTE S.A.S.
A8: Información general
A9: Origen | B9: Bogotá – Planta principal | D9: Destino | E9: Sopó – Cliente A
A10: Ruta alterna | B10: Autopista Norte – La Caro | D10: Sitios de parada autorizados | E10: Chía (peaje)
A11: Kms recorridos | B11: 42 km | D11: Duración | E11: 1 h 20 min
A12: Datos de contacto de la empresa
A13: Seguridad y Salud en el Trabajo | B13: Nombre / teléfono | D13: Operaciones | E13: Nombre / teléfono
A14: Organismos de apoyo disponibles
A15: Entidad / organismo | B15: Municipio / sede | C15: Contacto (si aplica) | D15: Teléfono 1 | E15: Teléfono 2
A16: Línea única de emergencias | B16: Nacional | C16: No aplica | D16: 123
A17: Tránsito y transporte | B17: Nacional | C17: No aplica | D17: #767
A18: Emergencias médicas | B18: Nacional | C18: No aplica | D18: 125
A19: Bomberos | B19: Nacional | C19: No aplica | D19: 119
A20: Cruz Roja | B20: Nacional | C20: No aplica | D20: 132
A21: Defensa Civil | B21: Nacional | C21: No aplica | D21: 144
A22: Policía Nacional | B22: Nacional | C22: No aplica | D22: 112
A23: Gaula del Ejército | B23: Nacional | C23: No aplica | D23: 147
A24: Línea única de emergencias | B24: Ciudad más cercana
A25: Tránsito y transporte | B25: Ciudad más cercana
A26: Bomberos | B26: Ciudad más cercana
A27: Policía Nacional | B27: Ciudad más cercana
A28: Mapa de la ruta
A29: Relacionar aquí el mapa de la ruta (insertar imagen o vincular mapa)
A37: Análisis de ruta — condiciones de riesgo (marque con X las más críticas)
A38: Señalización y normas de tránsito a tener en cuenta | D38: Calzada sin pavimentar / malla vial defectuosa
A39: Accidentes geográficos | D39: Alto flujo vehicular / cruces
A40: Riesgo público | D40: Curvas peligrosas
A41: Pendientes en ascenso / descenso | D41: Zonas pobladas, escolares y/o paso de ciclistas
A42: Señalización y/o infraestructura vial inadecuada | D42: Iluminación deficiente
A43: Intervenciones en la vía | D43: Presencia de semovientes
A44: Puente vehicular | D44: Naturales (desbordamientos, deslizamientos)
A46: Puntos de la ruta
A47: KM / vía / referencia | B47: Señales de tránsito | C47: Aspectos relevantes | D47: Controles existentes | E47: Recomendaciones de seguridad | F47: Riesgo más relevante

Sheet Reporte H1
A1: Informe general — Cumplimiento PESV e inventario
A2: Reporte de la Hoja 1
A4: Datos del cliente
A5: Empresa | B5: EMPRESA CLIENTE S.A.S. | D5: NIT | E5: 900.000.000-0
A6: Sede principal | B6: Planta principal | D6: Ciudad | E6: Bogotá D.C.
A7: Responsable PESV | B7: Roger Pérez | D7: Fecha de corte | E7: 31/05/2025
A8: Nivel PESV | B8: Avanzado | D8: N° informe | E8: RM-SV-2025-01
A10: Cumplimiento PESV (24 pasos)
A11: % cumplimiento global | B11: =AVERAGE('Hoja 1 · Generalidad'!F6:F29) -> 75 | D11: Pasos que cumplen | E11: =COUNTIF('Hoja 1 · Generalidad'!E6:E29,"Cumple") -> 11
A12: Pasos parciales | B12: =COUNTIF('Hoja 1 · Generalidad'!E6:E29,"Parcial") -> 10 | D12: Pasos sin cumplir | E12: =COUNTIF('Hoja 1 · Generalidad'!E6:E29,"No cumple") -> 3
A14: Inventario de movilidad
A15: Total actores viales | B15: ='Hoja 1 · Generalidad'!D42 -> 189 | D15: Total vehículos | E15: ='Hoja 1 · Generalidad'!D51 -> 69
A16: Ciudades con operación | B16: ='Hoja 1 · Generalidad'!D56 -> 5 | D16: Rutas activas | E16: ='Hoja 1 · Generalidad'!D57 -> 22

Sheet Reporte H2
A1: Informe de flota — Vehículos, mantenimiento y alertas
A2: Reporte de la Hoja 2
A4: Datos del cliente
A5: Empresa | B5: ='Reporte H1'!B5 -> EMPRESA CLIENTE S.A.S. | D5: Fecha de corte | E5: ='Reporte H1'!E7 -> 31/05/2025
A7: Estado de la flota
A8: Total de vehículos | B8: =COUNTA('Hoja 2 · Vehículos'!A6:A10) -> 5 | D8: Con alerta | E8: =COUNTIF('Hoja 2 · Vehículos'!AG6:AG10,"Alerta")+COUNTIF('Hoja 2 · Vehículos'!AG6:AG10,"Vencido") -> 3
A9: SOAT por vencer (≤30 d) | B9: =COUNTIFS('Hoja 2 · Vehículos'!K6:K10,">0",'Hoja 2 · Vehículos'!K6:K10,"<=30") -> 2 | D9: RTM por vencer (≤30 d) | E9: =COUNTIFS('Hoja 2 · Vehículos'!M6:M10,">0",'Hoja 2 · Vehículos'!M6:M10,"<=30") -> 1
A10: Documentos vencidos | B10: =COUNTIF('Hoja 2 · Vehículos'!K6:K10,"<=0")+COUNTIF('Hoja 2 · Vehículos'!M6:M10,"<=0") -> 1 | D10: Con comparendos | E10: =COUNTIF('Hoja 2 · Vehículos'!P6:P10,">0") -> 2

Sheet Reporte H3
A1: Informe de personas — Competencias y formación
A2: Reporte de la Hoja 3
A4: Datos del cliente
A5: Empresa | B5: ='Reporte H1'!B5 -> EMPRESA CLIENTE S.A.S. | D5: Fecha de corte | E5: ='Reporte H1'!E7 -> 31/05/2025
A7: Competencias del actor vial
A8: Total de conductores | B8: =COUNTA('Hoja 3 · Personas'!A6:A10) -> 5 | D8: % aprobados (ICC≥70) | E8: =COUNTIF('Hoja 3 · Personas'!AA6:AA10,"Aprobado")/COUNTA('Hoja 3 · Personas'!A6:A10) -> 0.6
A9: ICC promedio de la flota | B9: =ROUND(AVERAGE('Hoja 3 · Personas'!Z6:Z10),0) -> 75 | D9: No aprobados | E9: =COUNTIF('Hoja 3 · Personas'!AA6:AA10,"No aprobado") -> 2
A10: Licencias por vencer (≤30 d) | B10: =COUNTIFS('Hoja 3 · Personas'!J6:J10,">0",'Hoja 3 · Personas'!J6:J10,"<=30") -> 1 | D10: Licencias vencidas | E10: =COUNTIF('Hoja 3 · Personas'!J6:J10,"<=0") -> 1

Sheet Reporte H4
A1: Informe de rutograma — Riesgo de ruta
A2: Reporte de la Hoja 4
A4: Datos del cliente
A5: Empresa | B5: ='Reporte H1'!B5 -> EMPRESA CLIENTE S.A.S. | D5: Fecha de corte | E5: ='Reporte H1'!E7 -> 31/05/2025
A7: Riesgo de la ruta analizada
A8: Ruta | B8: ='Hoja 4 · Rutograma'!E6 -> R-01 | D8: Distancia | E8: Ver ficha
A9: Condiciones de riesgo marcadas | B9: Ver Hoja 4 | D9: Puntos analizados | E9: Ver Hoja 4

Sheet Panel de alertas
A1: Panel de alertas — consolidado
A2: Alertas activas de flota y conductores
A4: Vehículos
A5: Vehículos vencidos | B5: =COUNTIF('Hoja 2 · Vehículos'!AG6:AG10,"Vencido") -> 1 | D5: Vehículos en alerta | E5: =COUNTIF('Hoja 2 · Vehículos'!AG6:AG10,"Alerta") -> 2
A6: SOAT/RTM por vencer (≤30 d) | B6: =COUNTIFS('Hoja 2 · Vehículos'!K6:K10,">0",'Hoja 2 · Vehículos'!K6:K10,"<=30")+COUNTIFS('Hoja 2 · Vehículos'!M6:M10,">0",'Hoja 2 · Vehículos'!M6:M10,"<=30") -> 3 | D6: Con comparendos | E6: =COUNTIF('Hoja 2 · Vehículos'!P6:P10,">0") -> 2
A8: Conductores
A9: Licencias vencidas | B9: =COUNTIF('Hoja 3 · Personas'!J6:J10,"<=0") -> 1 | D9: Licencias por vencer (≤30 d) | E9: =COUNTIFS('Hoja 3 · Personas'!J6:J10,">0",'Hoja 3 · Personas'!J6:J10,"<=30") -> 1
A10: No aprobados (ICC<70) | B10: =COUNTIF('Hoja 3 · Personas'!AA6:AA10,"No aprobado") -> 2 | D10: Conductores en alerta | E10: =COUNTIF('Hoja 3 · Personas'!AB6:AB10,"Alerta")+COUNTIF('Hoja 3 · Personas'!AB6:AB10,"Licencia vencida") -> 3
A12: Para ver el detalle, filtra la columna Alerta en las hojas 2 y 3 por 'Alerta', 'Vencido' o 'Licencia vencida'.

Sheet Leyenda
A1: Leyenda y guía de uso
A3: Estructura del libro
A4: Diccionario: catálogo de todas las variables por categoría (mismo formato del libro de higiene).
A5: Hoja 1 · Generalidad: 24 pasos del PESV (Res. 40595/2022) + inventario de movilidad (incluye peatones, ciclistas y monopatines).
A6: Hoja 2 · Vehículos: registro amplio con documentos, rutina de mantenimiento (prueba de frenado, alineación, llantas), combustible y rendimiento, e ingeniería del vehículo. Admite varios conductores.
A7: Hoja 3 · Personas: competencias cognitivas (incluye manejo comentado diurno y nocturno), formación y licencia.
A8: Hoja 4 · Rutograma: formato TTI — información general, organismos de apoyo, mapa, condiciones de riesgo y puntos de la ruta.
A9: Reportes H1–H4 y Panel de alertas: informes resumen que se calculan solos desde las hojas.
A11: Colores y cálculo
A12: Amarillo = celda editable. Gris = celda calculada (no editar).
A13: Alertas de vehículos: vencimientos, comparendos, km de mantenimiento, anomalía de consumo (≥15%), labrado <2 mm o prueba de frenado en falla.
A14: ICC (Hoja 3) = promedio de las 9 evaluaciones; Aprobado si ICC ≥ 70. Alerta también si el estado de salud es 'No apto'.
... A18: Registro base: alimentará el dashboard visual en una fase posterior.
